~/fabric8-analytics-common/dashboard/repositories/fabric8-analytics-auth ~/fabric8-analytics-common/dashboard/repositories/fabric8-analytics-auth
created virtual environment CPython3.6.10.final.0-64 in 143ms
  creator CPython3Posix(dest=/home/msawood/fabric8-analytics-common/dashboard/repositories/fabric8-analytics-auth/venv, clear=False, global=False)
  seeder FromAppData(download=False, pip=latest, setuptools=latest, wheel=latest, via=copy, app_data_dir=/home/msawood/.local/share/virtualenv/seed-app-data/v1.0.1)
  activators PythonActivator,FishActivator,XonshActivator,CShellActivator,PowerShellActivator,BashActivator
Requirement already satisfied: pyflakes in ./venv/lib/python3.6/site-packages (2.2.0)
----------------------------------------------------
Checking source files for common errors in following
directories:
fabric8a_auth
tests
tools
----------------------------------------------------

fabric8a_auth/__init__.py
    Pass
fabric8a_auth/errors.py
    Pass
fabric8a_auth/auth.py
    Pass
tests/test_utility_functions.py
    Pass
tests/test_token_handling.py
    Pass
tests/__init__.py
    Pass
tests/test_errors_class.py
    Pass
tools/check_python_version.py
    Pass
----------------------------------------------------
Checking following source files for common errors:
setup.py
----------------------------------------------------

setup.py
    Pass
~/fabric8-analytics-common/dashboard/repositories/fabric8-analytics-auth
All checks passed for 9 source files
